<?xml version="1.0"?>
<robot xmlns:xacro="http://www.ros.org/wiki/xacro">

  <!-- Drive wheel macro -->
  <xacro:macro name="drive_wheel" params="prefix reflect">
    <!-- Constants for the wheel -->
    <xacro:property name="wheel_radius" value="0.0352" />
    <xacro:property name="wheel_width" value="0.0206" />
    <xacro:property name="wheel_mass" value="0.5" />
    <xacro:property name="wheel_joint_offset_y" value="0.14" />

    <link name="${prefix}_wheel_link">
      <inertial>
        <origin xyz="0 0 0" rpy="0 0 0"/>
        <mass value="${wheel_mass}"/>
        <inertia 
          ixx="${wheel_mass * (3*wheel_radius*wheel_radius + wheel_width*wheel_width) / 12}" 
          ixy="0" 
          ixz="0" 
          iyy="${wheel_mass * (3*wheel_radius*wheel_radius + wheel_width*wheel_width) / 12}" 
          iyz="0" 
          izz="${wheel_mass * wheel_radius*wheel_radius / 2}"/>
      </inertial>
      <visual>
        <origin xyz="0 0 0" rpy="${pi/2} 0 0"/>
        <geometry>
          <cylinder radius="${wheel_radius}" length="${wheel_width}"/>
        </geometry>
        <material name="robot_black"/>
      </visual>
      <collision>
        <origin xyz="0 0 0" rpy="${pi/2} 0 0"/>
        <geometry>
          <cylinder radius="${wheel_radius}" length="${wheel_width}"/>
        </geometry>
      </collision>
    </link>

    <joint name="${prefix}_wheel_joint" type="continuous">
      <parent link="base_link"/>
      <child link="${prefix}_wheel_link"/>
      <origin xyz="0 ${reflect * wheel_joint_offset_y} ${wheel_radius}" rpy="0 0 0"/>
      <axis xyz="0 1 0"/>
    </joint>

    <!-- Gazebo-specific properties -->
    <gazebo reference="${prefix}_wheel_link">
      <material>Gazebo/Black</material>
      <mu1>0.8</mu1>
      <mu2>0.8</mu2>
    </gazebo>
  </xacro:macro>

</robot>